[2022-06-03 00:52:37,027] {taskinstance.py:1160} INFO - Dependencies all met for <TaskInstance: nyc_bus_breakdown_pipeline.processing_data manual__2022-06-03T00:52:29.832993+00:00 [queued]>
[2022-06-03 00:52:37,048] {taskinstance.py:1160} INFO - Dependencies all met for <TaskInstance: nyc_bus_breakdown_pipeline.processing_data manual__2022-06-03T00:52:29.832993+00:00 [queued]>
[2022-06-03 00:52:37,048] {taskinstance.py:1357} INFO - 
--------------------------------------------------------------------------------
[2022-06-03 00:52:37,050] {taskinstance.py:1358} INFO - Starting attempt 1 of 2
[2022-06-03 00:52:37,051] {taskinstance.py:1359} INFO - 
--------------------------------------------------------------------------------
[2022-06-03 00:52:37,084] {taskinstance.py:1378} INFO - Executing <Task(PythonOperator): processing_data> on 2022-06-03 00:52:29.832993+00:00
[2022-06-03 00:52:37,094] {standard_task_runner.py:52} INFO - Started process 5323 to run task
[2022-06-03 00:52:37,101] {standard_task_runner.py:79} INFO - Running: ['***', 'tasks', 'run', 'nyc_bus_breakdown_pipeline', 'processing_data', 'manual__2022-06-03T00:52:29.832993+00:00', '--job-id', '113', '--raw', '--subdir', 'DAGS_FOLDER/nycbus_etl.py', '--cfg-path', '/tmp/tmphib_z312', '--error-file', '/tmp/tmpsn1ffgl6']
[2022-06-03 00:52:37,105] {standard_task_runner.py:80} INFO - Job 113: Subtask processing_data
[2022-06-03 00:52:37,222] {task_command.py:370} INFO - Running <TaskInstance: nyc_bus_breakdown_pipeline.processing_data manual__2022-06-03T00:52:29.832993+00:00 [running]> on host 8e84f5cf889f
[2022-06-03 00:52:37,348] {taskinstance.py:1572} INFO - Exporting the following env vars:
AIRFLOW_CTX_DAG_EMAIL=***@example.com
AIRFLOW_CTX_DAG_OWNER=***
AIRFLOW_CTX_DAG_ID=nyc_bus_breakdown_pipeline
AIRFLOW_CTX_TASK_ID=processing_data
AIRFLOW_CTX_EXECUTION_DATE=2022-06-03T00:52:29.832993+00:00
AIRFLOW_CTX_TRY_NUMBER=1
AIRFLOW_CTX_DAG_RUN_ID=manual__2022-06-03T00:52:29.832993+00:00
[2022-06-03 00:52:38,303] {taskinstance.py:1890} ERROR - Task failed with exception
Traceback (most recent call last):
  File "/home/airflow/.local/lib/python3.7/site-packages/airflow/operators/python.py", line 171, in execute
    return_value = self.execute_callable()
  File "/home/airflow/.local/lib/python3.7/site-packages/airflow/operators/python.py", line 189, in execute_callable
    return self.python_callable(*self.op_args, **self.op_kwargs)
  File "/opt/airflow/dags/etls/transformations.py", line 78, in processing_data
    df[['Have_You_Alerted_OPT', 'Has_Contractor_Notified_Schools', 'Has_Contractor_Notified_Parents']] = df[['Have_You_Alerted_OPT', 'Has_Contractor_Notified_Schools', 'Has_Contractor_Notified_Parents']].apply(lambda x: yes_or_no(x))
  File "/home/airflow/.local/lib/python3.7/site-packages/pandas/core/frame.py", line 8740, in apply
    return op.apply()
  File "/home/airflow/.local/lib/python3.7/site-packages/pandas/core/apply.py", line 688, in apply
    return self.apply_standard()
  File "/home/airflow/.local/lib/python3.7/site-packages/pandas/core/apply.py", line 812, in apply_standard
    results, res_index = self.apply_series_generator()
  File "/home/airflow/.local/lib/python3.7/site-packages/pandas/core/apply.py", line 828, in apply_series_generator
    results[i] = self.f(v)
  File "/opt/airflow/dags/etls/transformations.py", line 78, in <lambda>
    df[['Have_You_Alerted_OPT', 'Has_Contractor_Notified_Schools', 'Has_Contractor_Notified_Parents']] = df[['Have_You_Alerted_OPT', 'Has_Contractor_Notified_Schools', 'Has_Contractor_Notified_Parents']].apply(lambda x: yes_or_no(x))
  File "/opt/airflow/dags/etls/helpers.py", line 28, in yes_or_no
    return "Y" if string=="Yes" else "N"
  File "/home/airflow/.local/lib/python3.7/site-packages/pandas/core/generic.py", line 1538, in __nonzero__
    f"The truth value of a {type(self).__name__} is ambiguous. "
ValueError: The truth value of a Series is ambiguous. Use a.empty, a.bool(), a.item(), a.any() or a.all().
[2022-06-03 00:52:38,350] {taskinstance.py:1401} INFO - Marking task as UP_FOR_RETRY. dag_id=nyc_bus_breakdown_pipeline, task_id=processing_data, execution_date=20220603T005229, start_date=20220603T005237, end_date=20220603T005238
[2022-06-03 00:52:38,372] {standard_task_runner.py:97} ERROR - Failed to execute job 113 for task processing_data (The truth value of a Series is ambiguous. Use a.empty, a.bool(), a.item(), a.any() or a.all().; 5323)
[2022-06-03 00:52:38,401] {local_task_job.py:156} INFO - Task exited with return code 1
[2022-06-03 00:52:38,457] {local_task_job.py:273} INFO - 0 downstream tasks scheduled from follow-on schedule check
