[2022-06-02 23:28:05,764] {taskinstance.py:1160} INFO - Dependencies all met for <TaskInstance: nyc_bus_breakdown_pipeline.processing_data manual__2022-06-02T23:28:00.539502+00:00 [queued]>
[2022-06-02 23:28:05,783] {taskinstance.py:1160} INFO - Dependencies all met for <TaskInstance: nyc_bus_breakdown_pipeline.processing_data manual__2022-06-02T23:28:00.539502+00:00 [queued]>
[2022-06-02 23:28:05,784] {taskinstance.py:1357} INFO - 
--------------------------------------------------------------------------------
[2022-06-02 23:28:05,785] {taskinstance.py:1358} INFO - Starting attempt 1 of 2
[2022-06-02 23:28:05,785] {taskinstance.py:1359} INFO - 
--------------------------------------------------------------------------------
[2022-06-02 23:28:05,806] {taskinstance.py:1378} INFO - Executing <Task(PythonOperator): processing_data> on 2022-06-02 23:28:00.539502+00:00
[2022-06-02 23:28:05,830] {standard_task_runner.py:52} INFO - Started process 1254 to run task
[2022-06-02 23:28:05,836] {standard_task_runner.py:79} INFO - Running: ['***', 'tasks', 'run', 'nyc_bus_breakdown_pipeline', 'processing_data', 'manual__2022-06-02T23:28:00.539502+00:00', '--job-id', '105', '--raw', '--subdir', 'DAGS_FOLDER/nycbus_etl.py', '--cfg-path', '/tmp/tmpz215x659', '--error-file', '/tmp/tmpgitscdla']
[2022-06-02 23:28:05,838] {standard_task_runner.py:80} INFO - Job 105: Subtask processing_data
[2022-06-02 23:28:05,928] {task_command.py:370} INFO - Running <TaskInstance: nyc_bus_breakdown_pipeline.processing_data manual__2022-06-02T23:28:00.539502+00:00 [running]> on host 8e84f5cf889f
[2022-06-02 23:28:06,046] {taskinstance.py:1572} INFO - Exporting the following env vars:
AIRFLOW_CTX_DAG_EMAIL=***@example.com
AIRFLOW_CTX_DAG_OWNER=***
AIRFLOW_CTX_DAG_ID=nyc_bus_breakdown_pipeline
AIRFLOW_CTX_TASK_ID=processing_data
AIRFLOW_CTX_EXECUTION_DATE=2022-06-02T23:28:00.539502+00:00
AIRFLOW_CTX_TRY_NUMBER=1
AIRFLOW_CTX_DAG_RUN_ID=manual__2022-06-02T23:28:00.539502+00:00
[2022-06-02 23:28:06,710] {taskinstance.py:1890} ERROR - Task failed with exception
Traceback (most recent call last):
  File "/home/airflow/.local/lib/python3.7/site-packages/airflow/operators/python.py", line 171, in execute
    return_value = self.execute_callable()
  File "/home/airflow/.local/lib/python3.7/site-packages/airflow/operators/python.py", line 189, in execute_callable
    return self.python_callable(*self.op_args, **self.op_kwargs)
  File "/opt/airflow/dags/etls/transformations.py", line 90, in processing_data
    df.to_hdf(None),
TypeError: to_hdf() missing 1 required positional argument: 'key'
[2022-06-02 23:28:06,723] {taskinstance.py:1401} INFO - Marking task as UP_FOR_RETRY. dag_id=nyc_bus_breakdown_pipeline, task_id=processing_data, execution_date=20220602T232800, start_date=20220602T232805, end_date=20220602T232806
[2022-06-02 23:28:06,738] {standard_task_runner.py:97} ERROR - Failed to execute job 105 for task processing_data (to_hdf() missing 1 required positional argument: 'key'; 1254)
[2022-06-02 23:28:06,770] {local_task_job.py:156} INFO - Task exited with return code 1
[2022-06-02 23:28:06,830] {local_task_job.py:273} INFO - 0 downstream tasks scheduled from follow-on schedule check
