[2022-06-03 17:38:13,712] {taskinstance.py:1160} INFO - Dependencies all met for <TaskInstance: nyc_bus_breakdown_pipeline.load_data scheduled__2022-05-27T17:37:13.376465+00:00 [queued]>
[2022-06-03 17:38:13,725] {taskinstance.py:1160} INFO - Dependencies all met for <TaskInstance: nyc_bus_breakdown_pipeline.load_data scheduled__2022-05-27T17:37:13.376465+00:00 [queued]>
[2022-06-03 17:38:13,725] {taskinstance.py:1357} INFO - 
--------------------------------------------------------------------------------
[2022-06-03 17:38:13,726] {taskinstance.py:1358} INFO - Starting attempt 2 of 2
[2022-06-03 17:38:13,726] {taskinstance.py:1359} INFO - 
--------------------------------------------------------------------------------
[2022-06-03 17:38:13,749] {taskinstance.py:1378} INFO - Executing <Task(PythonOperator): load_data> on 2022-05-27 17:37:13.376465+00:00
[2022-06-03 17:38:13,755] {standard_task_runner.py:52} INFO - Started process 1179 to run task
[2022-06-03 17:38:13,761] {standard_task_runner.py:79} INFO - Running: ['***', 'tasks', 'run', 'nyc_bus_breakdown_pipeline', 'load_data', 'scheduled__2022-05-27T17:37:13.376465+00:00', '--job-id', '156', '--raw', '--subdir', 'DAGS_FOLDER/nycbus_etl.py', '--cfg-path', '/tmp/tmp7frd4yyr', '--error-file', '/tmp/tmp7xlghssq']
[2022-06-03 17:38:13,762] {standard_task_runner.py:80} INFO - Job 156: Subtask load_data
[2022-06-03 17:38:13,837] {task_command.py:370} INFO - Running <TaskInstance: nyc_bus_breakdown_pipeline.load_data scheduled__2022-05-27T17:37:13.376465+00:00 [running]> on host 9212bd95e1cf
[2022-06-03 17:38:14,182] {taskinstance.py:1572} INFO - Exporting the following env vars:
AIRFLOW_CTX_DAG_EMAIL=***@example.com
AIRFLOW_CTX_DAG_OWNER=***
AIRFLOW_CTX_DAG_ID=nyc_bus_breakdown_pipeline
AIRFLOW_CTX_TASK_ID=load_data
AIRFLOW_CTX_EXECUTION_DATE=2022-05-27T17:37:13.376465+00:00
AIRFLOW_CTX_TRY_NUMBER=2
AIRFLOW_CTX_DAG_RUN_ID=scheduled__2022-05-27T17:37:13.376465+00:00
[2022-06-03 17:38:56,325] {taskinstance.py:1890} ERROR - Task failed with exception
Traceback (most recent call last):
  File "/home/airflow/.local/lib/python3.7/site-packages/airflow/operators/python.py", line 171, in execute
    return_value = self.execute_callable()
  File "/home/airflow/.local/lib/python3.7/site-packages/airflow/operators/python.py", line 189, in execute_callable
    return self.python_callable(*self.op_args, **self.op_kwargs)
  File "/opt/airflow/dags/etls/loads.py", line 8, in load_csv
    host='nycbus-db.cjis73z6nngu.us-east-1.rds.amazonaws.com', port='5432'
  File "/home/airflow/.local/lib/python3.7/site-packages/psycopg2/__init__.py", line 122, in connect
    conn = _connect(dsn, connection_factory=connection_factory, **kwasync)
psycopg2.OperationalError: connection to server at "nycbus-db.cjis73z6nngu.us-east-1.rds.amazonaws.com" (23.21.247.109), port 5432 failed: Connection refused
	Is the server running on that host and accepting TCP/IP connections?
connection to server at "nycbus-db.cjis73z6nngu.us-east-1.rds.amazonaws.com" (23.21.247.109), port 5432 failed: Connection refused
	Is the server running on that host and accepting TCP/IP connections?

[2022-06-03 17:38:56,345] {taskinstance.py:1401} INFO - Marking task as FAILED. dag_id=nyc_bus_breakdown_pipeline, task_id=load_data, execution_date=20220527T173713, start_date=20220603T173813, end_date=20220603T173856
[2022-06-03 17:38:56,362] {standard_task_runner.py:97} ERROR - Failed to execute job 156 for task load_data (connection to server at "nycbus-db.cjis73z6nngu.us-east-1.rds.amazonaws.com" (23.21.247.109), port 5432 failed: Connection refused
	Is the server running on that host and accepting TCP/IP connections?
connection to server at "nycbus-db.cjis73z6nngu.us-east-1.rds.amazonaws.com" (23.21.247.109), port 5432 failed: Connection refused
	Is the server running on that host and accepting TCP/IP connections?
; 1179)
[2022-06-03 17:38:56,405] {local_task_job.py:156} INFO - Task exited with return code 1
[2022-06-03 17:38:56,432] {local_task_job.py:273} INFO - 0 downstream tasks scheduled from follow-on schedule check
