[2022-06-02 21:51:20,020] {taskinstance.py:1160} INFO - Dependencies all met for <TaskInstance: nyc_bus_breakdown_pipeline.processing_data manual__2022-06-02T21:51:05.232247+00:00 [queued]>
[2022-06-02 21:51:20,029] {taskinstance.py:1160} INFO - Dependencies all met for <TaskInstance: nyc_bus_breakdown_pipeline.processing_data manual__2022-06-02T21:51:05.232247+00:00 [queued]>
[2022-06-02 21:51:20,030] {taskinstance.py:1357} INFO - 
--------------------------------------------------------------------------------
[2022-06-02 21:51:20,031] {taskinstance.py:1358} INFO - Starting attempt 2 of 2
[2022-06-02 21:51:20,031] {taskinstance.py:1359} INFO - 
--------------------------------------------------------------------------------
[2022-06-02 21:51:20,047] {taskinstance.py:1378} INFO - Executing <Task(PythonOperator): processing_data> on 2022-06-02 21:51:05.232247+00:00
[2022-06-02 21:51:20,052] {standard_task_runner.py:52} INFO - Started process 134 to run task
[2022-06-02 21:51:20,055] {standard_task_runner.py:79} INFO - Running: ['***', 'tasks', 'run', 'nyc_bus_breakdown_pipeline', 'processing_data', 'manual__2022-06-02T21:51:05.232247+00:00', '--job-id', '48', '--raw', '--subdir', 'DAGS_FOLDER/nycbus_etl.py', '--cfg-path', '/tmp/tmprwrhq7at', '--error-file', '/tmp/tmpdtlfmmg9']
[2022-06-02 21:51:20,057] {standard_task_runner.py:80} INFO - Job 48: Subtask processing_data
[2022-06-02 21:51:20,111] {task_command.py:370} INFO - Running <TaskInstance: nyc_bus_breakdown_pipeline.processing_data manual__2022-06-02T21:51:05.232247+00:00 [running]> on host 2ac97db4f2c6
[2022-06-02 21:51:20,189] {taskinstance.py:1572} INFO - Exporting the following env vars:
AIRFLOW_CTX_DAG_EMAIL=***@example.com
AIRFLOW_CTX_DAG_OWNER=***
AIRFLOW_CTX_DAG_ID=nyc_bus_breakdown_pipeline
AIRFLOW_CTX_TASK_ID=processing_data
AIRFLOW_CTX_EXECUTION_DATE=2022-06-02T21:51:05.232247+00:00
AIRFLOW_CTX_TRY_NUMBER=2
AIRFLOW_CTX_DAG_RUN_ID=manual__2022-06-02T21:51:05.232247+00:00
[2022-06-02 21:51:20,790] {taskinstance.py:1890} ERROR - Task failed with exception
Traceback (most recent call last):
  File "/home/airflow/.local/lib/python3.7/site-packages/airflow/operators/python.py", line 171, in execute
    return_value = self.execute_callable()
  File "/home/airflow/.local/lib/python3.7/site-packages/airflow/operators/python.py", line 189, in execute_callable
    return self.python_callable(*self.op_args, **self.op_kwargs)
  File "/opt/airflow/dags/etls/transformations.py", line 69, in processing_data
    df = extract_first_number(df, "how_long_delayed")
  File "/opt/airflow/dags/etls/helpers.py", line 129, in extract_first_number
    df[column] = parallelize_on_rows(df[column], regex_number_finder)
  File "/opt/airflow/dags/etls/helpers.py", line 99, in parallelize_on_rows
    return parallelize(data, partial(run_on_subset, func), num_of_processes)
  File "/opt/airflow/dags/etls/helpers.py", line 87, in parallelize
    pool = Pool(num_of_processes)
  File "/usr/local/lib/python3.7/multiprocessing/context.py", line 119, in Pool
    context=self.get_context())
  File "/usr/local/lib/python3.7/multiprocessing/pool.py", line 176, in __init__
    self._repopulate_pool()
  File "/usr/local/lib/python3.7/multiprocessing/pool.py", line 241, in _repopulate_pool
    w.start()
  File "/usr/local/lib/python3.7/multiprocessing/process.py", line 110, in start
    'daemonic processes are not allowed to have children'
AssertionError: daemonic processes are not allowed to have children
[2022-06-02 21:51:20,812] {taskinstance.py:1401} INFO - Marking task as FAILED. dag_id=nyc_bus_breakdown_pipeline, task_id=processing_data, execution_date=20220602T215105, start_date=20220602T215120, end_date=20220602T215120
[2022-06-02 21:51:20,825] {standard_task_runner.py:97} ERROR - Failed to execute job 48 for task processing_data (daemonic processes are not allowed to have children; 134)
[2022-06-02 21:51:20,871] {local_task_job.py:156} INFO - Task exited with return code 1
[2022-06-02 21:51:20,913] {local_task_job.py:273} INFO - 0 downstream tasks scheduled from follow-on schedule check
