[2022-06-02 23:16:44,845] {taskinstance.py:1160} INFO - Dependencies all met for <TaskInstance: nyc_bus_breakdown_pipeline.processing_data manual__2022-06-02T23:16:30.812740+00:00 [queued]>
[2022-06-02 23:16:44,854] {taskinstance.py:1160} INFO - Dependencies all met for <TaskInstance: nyc_bus_breakdown_pipeline.processing_data manual__2022-06-02T23:16:30.812740+00:00 [queued]>
[2022-06-02 23:16:44,855] {taskinstance.py:1357} INFO - 
--------------------------------------------------------------------------------
[2022-06-02 23:16:44,855] {taskinstance.py:1358} INFO - Starting attempt 2 of 2
[2022-06-02 23:16:44,856] {taskinstance.py:1359} INFO - 
--------------------------------------------------------------------------------
[2022-06-02 23:16:44,870] {taskinstance.py:1378} INFO - Executing <Task(PythonOperator): processing_data> on 2022-06-02 23:16:30.812740+00:00
[2022-06-02 23:16:44,875] {standard_task_runner.py:52} INFO - Started process 573 to run task
[2022-06-02 23:16:44,879] {standard_task_runner.py:79} INFO - Running: ['***', 'tasks', 'run', 'nyc_bus_breakdown_pipeline', 'processing_data', 'manual__2022-06-02T23:16:30.812740+00:00', '--job-id', '92', '--raw', '--subdir', 'DAGS_FOLDER/nycbus_etl.py', '--cfg-path', '/tmp/tmpehpy3x_2', '--error-file', '/tmp/tmp0dq0ayp4']
[2022-06-02 23:16:44,880] {standard_task_runner.py:80} INFO - Job 92: Subtask processing_data
[2022-06-02 23:16:44,934] {task_command.py:370} INFO - Running <TaskInstance: nyc_bus_breakdown_pipeline.processing_data manual__2022-06-02T23:16:30.812740+00:00 [running]> on host 8e84f5cf889f
[2022-06-02 23:16:45,017] {taskinstance.py:1572} INFO - Exporting the following env vars:
AIRFLOW_CTX_DAG_EMAIL=***@example.com
AIRFLOW_CTX_DAG_OWNER=***
AIRFLOW_CTX_DAG_ID=nyc_bus_breakdown_pipeline
AIRFLOW_CTX_TASK_ID=processing_data
AIRFLOW_CTX_EXECUTION_DATE=2022-06-02T23:16:30.812740+00:00
AIRFLOW_CTX_TRY_NUMBER=2
AIRFLOW_CTX_DAG_RUN_ID=manual__2022-06-02T23:16:30.812740+00:00
[2022-06-02 23:16:45,974] {base.py:68} INFO - Using connection ID 's3_conn' for task execution.
[2022-06-02 23:16:45,975] {base_aws.py:210} INFO - Credentials retrieved from extra_config
[2022-06-02 23:16:46,223] {taskinstance.py:1890} ERROR - Task failed with exception
Traceback (most recent call last):
  File "/home/airflow/.local/lib/python3.7/site-packages/airflow/operators/python.py", line 171, in execute
    return_value = self.execute_callable()
  File "/home/airflow/.local/lib/python3.7/site-packages/airflow/operators/python.py", line 189, in execute_callable
    return self.python_callable(*self.op_args, **self.op_kwargs)
  File "/opt/airflow/dags/etls/transformations.py", line 85, in processing_data
    hook.load_file_obj(file_obj=df.to_hdf(name, key="df", mode='a', format="table"), key=name, bucket_name=bucket_name)
  File "/home/airflow/.local/lib/python3.7/site-packages/airflow/providers/amazon/aws/hooks/s3.py", line 63, in wrapper
    return func(*bound_args.args, **bound_args.kwargs)
  File "/home/airflow/.local/lib/python3.7/site-packages/airflow/providers/amazon/aws/hooks/s3.py", line 91, in wrapper
    return func(*bound_args.args, **bound_args.kwargs)
  File "/home/airflow/.local/lib/python3.7/site-packages/airflow/providers/amazon/aws/hooks/s3.py", line 722, in load_file_obj
    self._upload_file_obj(file_obj, key, bucket_name, replace, encrypt, acl_policy)
  File "/home/airflow/.local/lib/python3.7/site-packages/airflow/providers/amazon/aws/hooks/s3.py", line 748, in _upload_file_obj
    Config=self.transfer_config,
  File "/home/airflow/.local/lib/python3.7/site-packages/boto3/s3/inject.py", line 618, in upload_fileobj
    raise ValueError('Fileobj must implement read')
ValueError: Fileobj must implement read
[2022-06-02 23:16:46,239] {taskinstance.py:1401} INFO - Marking task as FAILED. dag_id=nyc_bus_breakdown_pipeline, task_id=processing_data, execution_date=20220602T231630, start_date=20220602T231644, end_date=20220602T231646
[2022-06-02 23:16:46,252] {standard_task_runner.py:97} ERROR - Failed to execute job 92 for task processing_data (Fileobj must implement read; 573)
[2022-06-02 23:16:46,296] {local_task_job.py:156} INFO - Task exited with return code 1
[2022-06-02 23:16:46,350] {local_task_job.py:273} INFO - 0 downstream tasks scheduled from follow-on schedule check
