[2022-06-03 02:08:26,499] {taskinstance.py:1160} INFO - Dependencies all met for <TaskInstance: nyc_bus_breakdown_pipeline.load_data manual__2022-06-03T02:07:41.671826+00:00 [queued]>
[2022-06-03 02:08:26,527] {taskinstance.py:1160} INFO - Dependencies all met for <TaskInstance: nyc_bus_breakdown_pipeline.load_data manual__2022-06-03T02:07:41.671826+00:00 [queued]>
[2022-06-03 02:08:26,528] {taskinstance.py:1357} INFO - 
--------------------------------------------------------------------------------
[2022-06-03 02:08:26,529] {taskinstance.py:1358} INFO - Starting attempt 2 of 2
[2022-06-03 02:08:26,529] {taskinstance.py:1359} INFO - 
--------------------------------------------------------------------------------
[2022-06-03 02:08:26,563] {taskinstance.py:1378} INFO - Executing <Task(PythonOperator): load_data> on 2022-06-03 02:07:41.671826+00:00
[2022-06-03 02:08:26,573] {standard_task_runner.py:52} INFO - Started process 914 to run task
[2022-06-03 02:08:26,582] {standard_task_runner.py:79} INFO - Running: ['***', 'tasks', 'run', 'nyc_bus_breakdown_pipeline', 'load_data', 'manual__2022-06-03T02:07:41.671826+00:00', '--job-id', '128', '--raw', '--subdir', 'DAGS_FOLDER/nycbus_etl.py', '--cfg-path', '/tmp/tmpl1ok4lgo', '--error-file', '/tmp/tmp476o98v5']
[2022-06-03 02:08:26,585] {standard_task_runner.py:80} INFO - Job 128: Subtask load_data
[2022-06-03 02:08:26,702] {task_command.py:370} INFO - Running <TaskInstance: nyc_bus_breakdown_pipeline.load_data manual__2022-06-03T02:07:41.671826+00:00 [running]> on host b7655f13eea6
[2022-06-03 02:08:26,875] {taskinstance.py:1572} INFO - Exporting the following env vars:
AIRFLOW_CTX_DAG_EMAIL=***@example.com
AIRFLOW_CTX_DAG_OWNER=***
AIRFLOW_CTX_DAG_ID=nyc_bus_breakdown_pipeline
AIRFLOW_CTX_TASK_ID=load_data
AIRFLOW_CTX_EXECUTION_DATE=2022-06-03T02:07:41.671826+00:00
AIRFLOW_CTX_TRY_NUMBER=2
AIRFLOW_CTX_DAG_RUN_ID=manual__2022-06-03T02:07:41.671826+00:00
[2022-06-03 02:08:26,879] {s3.py:861} INFO - Downloading source S3 file from Bucket nycsbus-*** with path 22_bus_data.csv
[2022-06-03 02:08:27,145] {base.py:68} INFO - Using connection ID 's3_conn' for task execution.
[2022-06-03 02:08:27,149] {base_aws.py:210} INFO - Credentials retrieved from extra_config
[2022-06-03 02:09:10,169] {taskinstance.py:1890} ERROR - Task failed with exception
Traceback (most recent call last):
  File "/home/airflow/.local/lib/python3.7/site-packages/airflow/operators/python.py", line 171, in execute
    return_value = self.execute_callable()
  File "/home/airflow/.local/lib/python3.7/site-packages/airflow/operators/python.py", line 189, in execute_callable
    return self.python_callable(*self.op_args, **self.op_kwargs)
  File "/opt/airflow/dags/etls/loads.py", line 12, in load_csv
    host='nycbus-db.cjis73z6nngu.us-east-1.rds.amazonaws.com', port='5432'
  File "/home/airflow/.local/lib/python3.7/site-packages/psycopg2/__init__.py", line 122, in connect
    conn = _connect(dsn, connection_factory=connection_factory, **kwasync)
psycopg2.OperationalError: connection to server at "nycbus-db.cjis73z6nngu.us-east-1.rds.amazonaws.com" (23.21.247.109), port 5432 failed: Connection refused
	Is the server running on that host and accepting TCP/IP connections?
connection to server at "nycbus-db.cjis73z6nngu.us-east-1.rds.amazonaws.com" (23.21.247.109), port 5432 failed: Connection refused
	Is the server running on that host and accepting TCP/IP connections?

[2022-06-03 02:09:10,192] {taskinstance.py:1401} INFO - Marking task as FAILED. dag_id=nyc_bus_breakdown_pipeline, task_id=load_data, execution_date=20220603T020741, start_date=20220603T020826, end_date=20220603T020910
[2022-06-03 02:09:10,214] {standard_task_runner.py:97} ERROR - Failed to execute job 128 for task load_data (connection to server at "nycbus-db.cjis73z6nngu.us-east-1.rds.amazonaws.com" (23.21.247.109), port 5432 failed: Connection refused
	Is the server running on that host and accepting TCP/IP connections?
connection to server at "nycbus-db.cjis73z6nngu.us-east-1.rds.amazonaws.com" (23.21.247.109), port 5432 failed: Connection refused
	Is the server running on that host and accepting TCP/IP connections?
; 914)
[2022-06-03 02:09:10,253] {local_task_job.py:156} INFO - Task exited with return code 1
[2022-06-03 02:09:10,305] {local_task_job.py:273} INFO - 0 downstream tasks scheduled from follow-on schedule check
