[2022-06-02 22:01:00,296] {taskinstance.py:1160} INFO - Dependencies all met for <TaskInstance: nyc_bus_breakdown_pipeline.processing_data manual__2022-06-02T22:00:45.011440+00:00 [queued]>
[2022-06-02 22:01:00,305] {taskinstance.py:1160} INFO - Dependencies all met for <TaskInstance: nyc_bus_breakdown_pipeline.processing_data manual__2022-06-02T22:00:45.011440+00:00 [queued]>
[2022-06-02 22:01:00,306] {taskinstance.py:1357} INFO - 
--------------------------------------------------------------------------------
[2022-06-02 22:01:00,307] {taskinstance.py:1358} INFO - Starting attempt 2 of 2
[2022-06-02 22:01:00,307] {taskinstance.py:1359} INFO - 
--------------------------------------------------------------------------------
[2022-06-02 22:01:00,321] {taskinstance.py:1378} INFO - Executing <Task(PythonOperator): processing_data> on 2022-06-02 22:00:45.011440+00:00
[2022-06-02 22:01:00,327] {standard_task_runner.py:52} INFO - Started process 153 to run task
[2022-06-02 22:01:00,331] {standard_task_runner.py:79} INFO - Running: ['***', 'tasks', 'run', 'nyc_bus_breakdown_pipeline', 'processing_data', 'manual__2022-06-02T22:00:45.011440+00:00', '--job-id', '89', '--raw', '--subdir', 'DAGS_FOLDER/nycbus_etl.py', '--cfg-path', '/tmp/tmpylu4wt01', '--error-file', '/tmp/tmpbnybtgjn']
[2022-06-02 22:01:00,332] {standard_task_runner.py:80} INFO - Job 89: Subtask processing_data
[2022-06-02 22:01:00,384] {task_command.py:370} INFO - Running <TaskInstance: nyc_bus_breakdown_pipeline.processing_data manual__2022-06-02T22:00:45.011440+00:00 [running]> on host 8e84f5cf889f
[2022-06-02 22:01:00,456] {taskinstance.py:1572} INFO - Exporting the following env vars:
AIRFLOW_CTX_DAG_EMAIL=***@example.com
AIRFLOW_CTX_DAG_OWNER=***
AIRFLOW_CTX_DAG_ID=nyc_bus_breakdown_pipeline
AIRFLOW_CTX_TASK_ID=processing_data
AIRFLOW_CTX_EXECUTION_DATE=2022-06-02T22:00:45.011440+00:00
AIRFLOW_CTX_TRY_NUMBER=2
AIRFLOW_CTX_DAG_RUN_ID=manual__2022-06-02T22:00:45.011440+00:00
[2022-06-02 22:01:01,521] {base.py:68} INFO - Using connection ID 's3_conn' for task execution.
[2022-06-02 22:01:01,522] {base_aws.py:210} INFO - Credentials retrieved from extra_config
[2022-06-02 22:01:01,782] {taskinstance.py:1890} ERROR - Task failed with exception
Traceback (most recent call last):
  File "/home/airflow/.local/lib/python3.7/site-packages/airflow/operators/python.py", line 171, in execute
    return_value = self.execute_callable()
  File "/home/airflow/.local/lib/python3.7/site-packages/airflow/operators/python.py", line 189, in execute_callable
    return self.python_callable(*self.op_args, **self.op_kwargs)
  File "/opt/airflow/dags/etls/transformations.py", line 85, in processing_data
    hook.load_file(filename=df.to_hdf(name, key="df", mode='a', format="table"), key=name, bucket_name=bucket_name)
  File "/home/airflow/.local/lib/python3.7/site-packages/airflow/providers/amazon/aws/hooks/s3.py", line 63, in wrapper
    return func(*bound_args.args, **bound_args.kwargs)
  File "/home/airflow/.local/lib/python3.7/site-packages/airflow/providers/amazon/aws/hooks/s3.py", line 91, in wrapper
    return func(*bound_args.args, **bound_args.kwargs)
  File "/home/airflow/.local/lib/python3.7/site-packages/airflow/providers/amazon/aws/hooks/s3.py", line 615, in load_file
    client.upload_file(filename, bucket_name, key, ExtraArgs=extra_args, Config=self.transfer_config)
  File "/home/airflow/.local/lib/python3.7/site-packages/boto3/s3/inject.py", line 148, in upload_file
    callback=Callback,
  File "/home/airflow/.local/lib/python3.7/site-packages/boto3/s3/transfer.py", line 288, in upload_file
    future.result()
  File "/home/airflow/.local/lib/python3.7/site-packages/s3transfer/futures.py", line 103, in result
    return self._coordinator.result()
  File "/home/airflow/.local/lib/python3.7/site-packages/s3transfer/futures.py", line 266, in result
    raise self._exception
  File "/home/airflow/.local/lib/python3.7/site-packages/s3transfer/tasks.py", line 269, in _main
    self._submit(transfer_future=transfer_future, **kwargs)
  File "/home/airflow/.local/lib/python3.7/site-packages/s3transfer/upload.py", line 585, in _submit
    upload_input_manager.provide_transfer_size(transfer_future)
  File "/home/airflow/.local/lib/python3.7/site-packages/s3transfer/upload.py", line 244, in provide_transfer_size
    self._osutil.get_file_size(transfer_future.meta.call_args.fileobj)
  File "/home/airflow/.local/lib/python3.7/site-packages/s3transfer/utils.py", line 247, in get_file_size
    return os.path.getsize(filename)
  File "/usr/local/lib/python3.7/genericpath.py", line 50, in getsize
    return os.stat(filename).st_size
FileNotFoundError: [Errno 2] No such file or directory: 'None'
[2022-06-02 22:01:01,801] {taskinstance.py:1401} INFO - Marking task as FAILED. dag_id=nyc_bus_breakdown_pipeline, task_id=processing_data, execution_date=20220602T220045, start_date=20220602T220100, end_date=20220602T220101
[2022-06-02 22:01:01,815] {standard_task_runner.py:97} ERROR - Failed to execute job 89 for task processing_data ([Errno 2] No such file or directory: 'None'; 153)
[2022-06-02 22:01:01,830] {local_task_job.py:156} INFO - Task exited with return code 1
[2022-06-02 22:01:01,867] {local_task_job.py:273} INFO - 0 downstream tasks scheduled from follow-on schedule check
